Workbook
Name _GoBack: Справочник!#REF!
Name Astra: #REF!
Name ESXi: #REF!
Name GGG: #REF!
Name HDD__Bronze: #REF!
Name HDD__Gold: #REF!
Name HDD__Iron: #REF!
Name HDD__Silver: #REF!
Name OC: #REF!
Name OEL: #REF!
Name PosEnt: #REF!
Name PosEnt_1С: #REF!
Name PosSt: #REF!
Name RHEL: #REF!
Name Service_File: #REF!
Name Service_Lin: #REF!
Name Service_NSX: #REF!
Name Service_Pos: #REF!
Name Service_SQL: #REF!
Name Service_Term: #REF!
Name Service_Win: #REF!
Name SQL: #REF!
Name USB: #REF!
Name VATS_BASE: #REF!
Name VATS_CLGATE: #REF!
Name VATS_ENH: #REF!
Name VATS_GATE: #REF!
Name VATS_STD: #REF!
Name vCPU: #REF!
Name vGPU: #REF!
Name vRAM: #REF!
Name WIN: #REF!
Name Разработка_АЗ_для_ЗнИ_на_подключение_площадки: #REF!
Name СРК: #REF!

Sheet Справочник
A1: Фамилия Имя Отчество | B1: Должность | C1: № Кабинета | D1: № Телефона | E1: № Корпоративный мобильный телефон | F1: Тип телефонной линии | G1: Звонок в TrueConf | H1: Звонок на № телефона с TrueConf | I1: ID TrueConf | J1: #телефона
A2: ИНФОРМАЦИЯ ДЛЯ СЛУЖЕБНОГО ПОЛЬЗОВАНИЯ | J2: =IF(D2=""," ",CONCATENATE("051",D2))
J3: =IF(D3=""," ",CONCATENATE("051",D3))
A4: РУКОВОДСТВО | J4: =IF(D4=""," ",CONCATENATE("051",D4))
J5: =IF(D5=""," ",CONCATENATE("051",D5))
A6: Баринов Александр Александрович | B6: Генеральный директор | D6: 46703 | J6: =IF(D6=""," ",CONCATENATE("051",D6)) -> 05146703
J7: =IF(D7=""," ",CONCATENATE("051",D7))
A8: Онищук Юлиана Валерьевна | B8: Помощник руководителя | D8: 46703 | E8: 9323230085 | G8: =IF(I8="","",HYPERLINK(CONCATENATE("trueconf:",I8),"Вызов по TrueConf")) -> Вызов по TrueConf | H8: =IF(J8=" ","",_xlfn.IFNA(HYPERLINK("Trueconf:#tel:"&J8,"Позвонить на № телефона"),"")) -> Позвонить на № телефона | I8: =IF(A8="","",IFERROR(VLOOKUP(A8,'ID TrueConf'!$P$2:$Q$4300,2,0),"")) -> onishchuk.yuv@tc7.pp.gazprom-neft.ru | J8: =IF(D8=""," ",CONCATENATE("051",D8)) -> 05146703
G9: =IF(I9="","",HYPERLINK(CONCATENATE("trueconf:",I9),"Вызов по TrueConf")) | H9: =IF(J9=" ","",_xlfn.IFNA(HYPERLINK("Trueconf:#tel:"&J9,"Позвонить на № телефона"),"")) | I9: =IF(A9="","",IFERROR(VLOOKUP(A9,'ID TrueConf'!$P$2:$Q$4300,2,0),"")) | J9: =IF(D9=""," ",CONCATENATE("051",D9))
B10: Операционный директор | D10: 46877 | G10: =IF(I10="","",HYPERLINK(CONCATENATE("trueconf:",I10),"Вызов по TrueConf")) | H10: =IF(J10=" ","",_xlfn.IFNA(HYPERLINK("Trueconf:#tel:"&J10,"Позвонить на № телефона"),"")) -> Позвонить на № телефона | I10: =IF(A10="","",IFERROR(VLOOKUP(A10,'ID TrueConf'!$P$2:$Q$4300,2,0),"")) | J10: =IF(D10=""," ",CONCATENATE("051",D10)) -> 05146877
A11: Бирюкова Мария Евгеньевна | B11: Специалист | D11: 43985 | E11: 982-573-98-47 | G11: =IF(I11="","",HYPERLINK(CONCATENATE("trueconf:",I11),"Вызов по TrueConf")) -> Вызов по TrueConf | H11: =IF(J11=" ","",_xlfn.IFNA(HYPERLINK("Trueconf:#tel:"&J11,"Позвонить на № телефона"),"")) -> Позвонить на № телефона | I11: =IF(A11="","",IFERROR(VLOOKUP(A11,'ID TrueConf'!$P$2:$Q$4300,2,0),"")) -> biryukova.me@tc20.pp.gazprom-neft.ru | J11: =IF(D11=""," ",CONCATENATE("051",D11)) -> 05143985
G12: =IF(I12="","",HYPERLINK(CONCATENATE("trueconf:",I12),"Вызов по TrueConf")) | H12: =IF(J12=" ","",_xlfn.IFNA(HYPERLINK("Trueconf:#tel:"&J12,"Позвонить на № телефона"),"")) | I12: =IF(A12="","",IFERROR(VLOOKUP(A12,'ID TrueConf'!$P$2:$Q$4300,2,0),"")) | J12: =IF(D12=""," ",CONCATENATE("051",D12))
A13: Доронин Евгений Васильевич | B13: Технический директор | D13: 46484 | G13: =IF(I13="","",HYPERLINK(CONCATENATE("trueconf:",I13),"Вызов по TrueConf")) -> Вызов по TrueConf | H13: =IF(J13=" ","",_xlfn.IFNA(HYPERLINK("Trueconf:#tel:"&J13,"Позвонить на № телефона"),"")) -> Позвонить на № телефона | I13: =IF(A13="","",IFERROR(VLOOKUP(A13,'ID TrueConf'!$P$2:$Q$4300,2,0),"")) -> doronin.ev@tc16.pp.gazprom-neft.ru | J13: =IF(D13=""," ",CONCATENATE("051",D13)) -> 05146484
A14: Шарапова Анна Вадимовна | B14: Ведущий специалист | D14: 46140 | G14: =IF(I14="","",HYPERLINK(CONCATENATE("trueconf:",I14),"Вызов по TrueConf")) -> Вызов по TrueConf | H14: =IF(J14=" ","",_xlfn.IFNA(HYPERLINK("Trueconf:#tel:"&J14,"Позвонить на № телефона"),"")) -> Позвонить на № телефона | I14: =IF(A14="","",IFERROR(VLOOKUP(A14,'ID TrueConf'!$P$2:$Q$4300,2,0),"")) -> sharapova.av@tc19.pp.gazprom-neft.ru | J14: =IF(D14=""," ",CONCATENATE("051",D14)) -> 05146140
G15: =IF(I15="","",HYPERLINK(CONCATENATE("trueconf:",I15),"Вызов по TrueConf")) | H15: =IF(J15=" ","",_xlfn.IFNA(HYPERLINK("Trueconf:#tel:"&J15,"Позвонить на № телефона"),"")) | I15: =IF(A15="","",IFERROR(VLOOKUP(A15,'ID TrueConf'!$P$2:$Q$4300,2,0),"")) | J15: =IF(D15=""," ",CONCATENATE("051",D15))
A16: Сейдалиев Тимур Фаррухович | B16: Заместитель генерального директора по экономике и финансам | D16: 46400 | G16: =IF(I16="","",HYPERLINK(CONCATENATE("trueconf:",I16),"Вызов по TrueConf")) -> Вызов по TrueConf | H16: =IF(J16=" ","",_xlfn.IFNA(HYPERLINK("Trueconf:#tel:"&J16,"Позвонить на № телефона"),"")) -> Позвонить на № телефона | I16: =IF(A16="","",IFERROR(VLOOKUP(A16,'ID TrueConf'!$P$2:$Q$4300,2,0),"")) -> seydaliev.tf@tc12.pp.gazprom-neft.ru | J16: =IF(D16=""," ",CONCATENATE("051",D16)) -> 05146400
G17: =IF(I17="","",HYPERLINK(CONCATENATE("trueconf:",I17),"Вызов по TrueConf")) | H17: =IF(J17=" ","",_xlfn.IFNA(HYPERLINK("Trueconf:#tel:"&J17,"Позвонить на № телефона"),"")) | I17: =IF(A17="","",IFERROR(VLOOKUP(A17,'ID TrueConf'!$P$2:$Q$4300,2,0),"")) | J17: =IF(D17=""," ",CONCATENATE("051",D17))
A18: Дубенец Андрей Викторович | B18: Заместитель генерального директора по обеспечению производства | D18: 46913 | G18: =IF(I18="","",HYPERLINK(CONCATENATE("trueconf:",I18),"Вызов по TrueConf")) -> Вызов по TrueConf | H18: =IF(J18=" ","",_xlfn.IFNA(HYPERLINK("Trueconf:#tel:"&J18,"Позвонить на № телефона"),"")) -> Позвонить на № телефона | I18: =IF(A18="","",IFERROR(VLOOKUP(A18,'ID TrueConf'!$P$2:$Q$4300,2,0),"")) -> dubenets.av@tc11.pp.gazprom-neft.ru | J18: =IF(D18=""," ",CONCATENATE("051",D18)) -> 05146913
G19: =IF(I19="","",HYPERLINK(CONCATENATE("trueconf:",I19),"Вызов по TrueConf")) | H19: =IF(J19=" ","",_xlfn.IFNA(HYPERLINK("Trueconf:#tel:"&J19,"Позвонить на № телефона"),"")) | I19: =IF(A19="","",IFERROR(VLOOKUP(A19,'ID TrueConf'!$P$2:$Q$4300,2,0),"")) | J19: =IF(D19=""," ",CONCATENATE("051",D19))
A20: Зимогляд Михаил Борисович | B20: Директор по вводу новых мощностей | D20: 46611 | G20: =IF(I20="","",HYPERLINK(CONCATENATE("trueconf:",I20),"Вызов по TrueConf")) | H20: =IF(J20=" ","",_xlfn.IFNA(HYPERLINK("Trueconf:#tel:"&J20,"Позвонить на № телефона"),"")) -> Позвонить на № телефона | I20: =IF(A20="","",IFERROR(VLOOKUP(A20,'ID TrueConf'!$P$2:$Q$4300,2,0),"")) | J20: =IF(D20=""," ",CONCATENATE("051",D20)) -> 05146611
G21: =IF(I21="","",HYPERLINK(CONCATENATE("trueconf:",I21),"Вызов по TrueConf")) | H21: =IF(J21=" ","",_xlfn.IFNA(HYPERLINK("Trueconf:#tel:"&J21,"Позвонить на № телефона"),"")) | I21: =IF(A21="","",IFERROR(VLOOKUP(A21,'ID TrueConf'!$P$2:$Q$4300,2,0),"")) | J21: =IF(D21=""," ",CONCATENATE("051",D21))
A22: Игитов Семен Михайлович | B22: Директор по геологии и разработке, концептуальному проектированию - главный геолог | D22: 46911 | G22: =IF(I22="","",HYPERLINK(CONCATENATE("trueconf:",I22),"Вызов по TrueConf")) -> Вызов по TrueConf | H22: =IF(J22=" ","",_xlfn.IFNA(HYPERLINK("Trueconf:#tel:"&J22,"Позвонить на № телефона"),"")) -> Позвонить на № телефона | I22: =IF(A22="","",IFERROR(VLOOKUP(A22,'ID TrueConf'!$P$2:$Q$4300,2,0),"")) -> igitov.sm@tc11.pp.gazprom-neft.ru | J22: =IF(D22=""," ",CONCATENATE("051",D22)) -> 05146911
G23: =IF(I23="","",HYPERLINK(CONCATENATE("trueconf:",I23),"Вызов по TrueConf")) | H23: =IF(J23=" ","",_xlfn.IFNA(HYPERLINK("Trueconf:#tel:"&J23,"Позвонить на № телефона"),"")) | I23: =IF(A23="","",IFERROR(VLOOKUP(A23,'ID TrueConf'!$P$2:$Q$4300,2,0),"")) | J23: =IF(D23=""," ",CONCATENATE("051",D23))
A24: Платоненкова Наталья Анатольевна | B24: Заместитель генерального директора по правовым и имущественным вопросам | D24: 46575 | G24: =IF(I24="","",HYPERLINK(CONCATENATE("trueconf:",I24),"Вызов по TrueConf")) -> Вызов по TrueConf | H24: =IF(J24=" ","",_xlfn.IFNA(HYPERLINK("Trueconf:#tel:"&J24,"Позвонить на № телефона"),"")) -> Позвонить на № телефона | I24: platonenkova.na@tc6.pp.gazprom-neft.ru | J24: =IF(D24=""," ",CONCATENATE("051",D24)) -> 05146575
G25: =IF(I25="","",HYPERLINK(CONCATENATE("trueconf:",I25),"Вызов по TrueConf")) | H25: =IF(J25=" ","",_xlfn.IFNA(HYPERLINK("Trueconf:#tel:"&J25,"Позвонить на № телефона"),"")) | I25: =IF(A25="","",IFERROR(VLOOKUP(A25,'ID TrueConf'!$P$2:$Q$4300,2,0),"")) | J25: =IF(D25=""," ",CONCATENATE("051",D25))
A26: Фазлирахманов Фархат Салихович | B26: Директор по капитальному строительству | D26: 41793 | G26: =IF(I26="","",HYPERLINK(CONCATENATE("trueconf:",I26),"Вызов по TrueConf")) -> Вызов по TrueConf | H26: =IF(J26=" ","",_xlfn.IFNA(HYPERLINK("Trueconf:#tel:"&J26,"Позвонить на № телефона"),"")) -> Позвонить на № телефона | I26: =IF(A26="","",IFERROR(VLOOKUP(A26,'ID TrueConf'!$P$2:$Q$4300,2,0),"")) -> fazlirakhmanov.fs@tc7.pp.gazprom-neft.ru | J26: =IF(D26=""," ",CONCATENATE("051",D26)) -> 05141793
A27: Стоянчук Наталья Юрьевна | B27: Специалист | D27: 41479 | G27: =IF(I27="","",HYPERLINK(CONCATENATE("trueconf:",I27),"Вызов по TrueConf")) -> Вызов по TrueConf | H27: =IF(J27=" ","",_xlfn.IFNA(HYPERLINK("Trueconf:#tel:"&J27,"Позвонить на № телефона"),"")) -> Позвонить на № телефона | I27: =IF(A27="","",IFERROR(VLOOKUP(A27,'ID TrueConf'!$P$2:$Q$4300,2,0),"")) -> stoyanchuk.nyu@tc13.pp.gazprom-neft.ru | J27: =IF(D27=""," ",CONCATENATE("051",D27)) -> 05141479
G28: =IF(I28="","",HYPERLINK(CONCATENATE("trueconf:",I28),"Вызов по TrueConf")) | H28: =IF(J28=" ","",_xlfn.IFNA(HYPERLINK("Trueconf:#tel:"&J28,"Позвонить на № телефона"),"")) | I28: =IF(A28="","",IFERROR(VLOOKUP(A28,'ID TrueConf'!$P$2:$Q$4300,2,0),"")) | J28: =IF(D28=""," ",CONCATENATE("051",D28))
A29: Ханипов Ильмир Фаилович | B29: Директор по перспективному развитию и управлению портфелем | D29: 46010 | G29: =IF(I29="","",HYPERLINK(CONCATENATE("trueconf:",I29),"Вызов по TrueConf")) -> Вызов по TrueConf | H29: =IF(J29=" ","",_xlfn.IFNA(HYPERLINK("Trueconf:#tel:"&J29,"Позвонить на № телефона"),"")) -> Позвонить на № телефона | I29: =IF(A29="","",IFERROR(VLOOKUP(A29,'ID TrueConf'!$P$2:$Q$4300,2,0),"")) -> khanipov.if@tc11.pp.gazprom-neft.ru | J29: =IF(D29=""," ",CONCATENATE("051",D29)) -> 05146010
G30: =IF(I30="","",HYPERLINK(CONCATENATE("trueconf:",I30),"Вызов по TrueConf")) | H30: =IF(J30=" ","",_xlfn.IFNA(HYPERLINK("Trueconf:#tel:"&J30,"Позвонить на № телефона"),"")) | I30: =IF(A30="","",IFERROR(VLOOKUP(A30,'ID TrueConf'!$P$2:$Q$4300,2,0),"")) | J30: =IF(D30=""," ",CONCATENATE("051",D30))
A31: Плотников Артем Витальевич | B31: Заместитель генерального директора по производственной и экологической безопасности | C31: АБК-1 | D31: 46501 | G31: =IF(I31="","",HYPERLINK(CONCATENATE("trueconf:",I31),"Вызов по TrueConf")) -> Вызов по TrueConf | H31: =IF(J31=" ","",_xlfn.IFNA(HYPERLINK("Trueconf:#tel:"&J31,"Позвонить на № телефона"),"")) -> Позвонить на № телефона | I31: =IF(A31="","",IFERROR(VLOOKUP(A31,'ID TrueConf'!$P$2:$Q$4300,2,0),"")) -> plotnikov.avit@tc11.pp.gazprom-neft.ru | J31: =IF(D31=""," ",CONCATENATE("051",D31)) -> 05146501
G32: =IF(I32="","",HYPERLINK(CONCATENATE("trueconf:",I32),"Вызов по TrueConf")) | H32: =IF(J32=" ","",_xlfn.IFNA(HYPERLINK("Trueconf:#tel:"&J32,"Позвонить на № телефона"),"")) | I32: =IF(A32="","",IFERROR(VLOOKUP(A32,'ID TrueConf'!$P$2:$Q$4300,2,0),"")) | J32: =IF(D32=""," ",CONCATENATE("051",D32))
G33: =IF(I33="","",HYPERLINK(CONCATENATE("trueconf:",I33),"Вызов по TrueConf")) | H33: =IF(J33=" ","",_xlfn.IFNA(HYPERLINK("Trueconf:#tel:"&J33,"Позвонить на № телефона"),"")) | I33: =IF(A33="","",IFERROR(VLOOKUP(A33,'ID TrueConf'!$P$2:$Q$4300,2,0),"")) | J33: =IF(D33=""," ",CONCATENATE("051",D33))
A34: Матвиенко Николай Николаевич | B34: Заместитель генерального директора по корпоративной защите | D34: 42187 | G34: =IF(I34="","",HYPERLINK(CONCATENATE("trueconf:",I34),"Вызов по TrueConf")) -> Вызов по TrueConf | H34: =IF(J34=" ","",_xlfn.IFNA(HYPERLINK("Trueconf:#tel:"&J34,"Позвонить на № телефона"),"")) -> Позвонить на № телефона | I34: =IF(A34="","",IFERROR(VLOOKUP(A34,'ID TrueConf'!$P$2:$Q$4300,2,0),"")) -> matvienko.nn@tc14.pp.gazprom-neft.ru | J34: =IF(D34=""," ",CONCATENATE("051",D34)) -> 05142187
G35: =IF(I35="","",HYPERLINK(CONCATENATE("trueconf:",I35),"Вызов по TrueConf")) | H35: =IF(J35=" ","",_xlfn.IFNA(HYPERLINK("Trueconf:#tel:"&J35,"Позвонить на № телефона"),"")) | I35: =IF(A35="","",IFERROR(VLOOKUP(A35,'ID TrueConf'!$P$2:$Q$4300,2,0),"")) | J35: =IF(D35=""," ",CONCATENATE("051",D35))
A36: Гордиенко Сергей Викторович | B36: Заместитель генерального директора по работе с персоналом и организационному развитию | C36: АБК-1, 2 этаж | D36: 46090 | G36: =IF(I36="","",HYPERLINK(CONCATENATE("trueconf:",I36),"Вызов по TrueConf")) -> Вызов по TrueConf | H36: =IF(J36=" ","",_xlfn.IFNA(HYPERLINK("Trueconf:#tel:"&J36,"Позвонить на № телефона"),"")) -> Позвонить на № телефона | I36: =IF(A36="","",IFERROR(VLOOKUP(A36,'ID TrueConf'!$P$2:$Q$4300,2,0),"")) -> gordienko.sv@tc12.pp.gazprom-neft.ru | J36: =IF(D36=""," ",CONCATENATE("051",D36)) -> 05146090
G37: =IF(I37="","",HYPERLINK(CONCATENATE("trueconf:",I37),"Вызов по TrueConf")) | H37: =IF(J37=" ","",_xlfn.IFNA(HYPERLINK("Trueconf:#tel:"&J37,"Позвонить на № телефона"),"")) | I37: =IF(A37="","",IFERROR(VLOOKUP(A37,'ID TrueConf'!$P$2:$Q$4300,2,0),"")) | J37: =IF(D37=""," ",CONCATENATE("051",D37))
B38: Директор по бизнес-трансформации | G38: =IF(I38="","",HYPERLINK(CONCATENATE("trueconf:",I38),"Вызов по TrueConf")) | H38: =IF(J38=" ","",_xlfn.IFNA(HYPERLINK("Trueconf:#tel:"&J38,"Позвонить на № телефона"),"")) | I38: =IF(A38="","",IFERROR(VLOOKUP(A38,'ID TrueConf'!$P$2:$Q$4300,2,0),"")) | J38: =IF(D38=""," ",CONCATENATE("051",D38))
G39: =IF(I39="","",HYPERLINK(CONCATENATE("trueconf:",I39),"Вызов по TrueConf")) | H39: =IF(J39=" ","",_xlfn.IFNA(HYPERLINK("Trueconf:#tel:"&J39,"Позвонить на № телефона"),"")) | I39: =IF(A39="","",IFERROR(VLOOKUP(A39,'ID TrueConf'!$P$2:$Q$4300,2,0),"")) | J39: =IF(D39=""," ",CONCATENATE("051",D39))
A40: Иванов Михаил Григорьевич | B40: Директор по газу | D40: 46664 | G40: =IF(I40="","",HYPERLINK(CONCATENATE("trueconf:",I40),"Вызов по TrueConf")) -> Вызов по TrueConf | H40: =IF(J40=" ","",_xlfn.IFNA(HYPERLINK("Trueconf:#tel:"&J40,"Позвонить на № телефона"),"")) -> Позвонить на № телефона | I40: =IF(A40="","",IFERROR(VLOOKUP(A40,'ID TrueConf'!$P$2:$Q$4300,2,0),"")) -> ivanov.mgr@tc2.pp.gazprom-neft.ru | J40: =IF(D40=""," ",CONCATENATE("051",D40)) -> 05146664
...

Sheet ID TrueConf
A1: № | B1: Тип объекта обслуживания | C1: Объект обслуживания | D1: Период | E1: Компонент | F1: Тариф | G1: Количество | H1: Дней потребления | I1: Начислено руб. (без НДС) | J1: Целевой SLA, % | K1: Фактический SLA, % | L1: Скидка по SLA, руб. (без НДС) | M1: Итого со скидкой, руб. (без НДС) (индикативно) | N1: Комментарий заказчика | O1: Комментарий исполнителя | P1: Комментарий | Q1: Атрибут | R1: сверка
A2: 1 | B2: Учетная запись | C2: gaysin.rr | D2: ТЕКУЩИЙ ПЕРИОД | E2: Учетная запись ВКС | F2: 1249.63 | G2: 1 | H2: 28 | I2: 1249.63 | J2: 96.84 | K2: 100 | L2: 0 | M2: 1249.63 | P2: Гайсин Руслан Рамилевич | Q2: gaysin.rr@tc12.pp.gazprom-neft.ru | R2: =VLOOKUP(Таблица3[[#This Row],[Комментарий]],Справочник!$A$6:$B$4224,2,0) -> Начальник отдела
A3: 2 | B3: Учетная запись | C3: letko.ii | D3: ТЕКУЩИЙ ПЕРИОД | E3: Учетная запись ВКС | F3: 1249.63 | G3: 1 | H3: 28 | I3: 1249.63 | J3: 96.84 | K3: 100 | L3: 0 | M3: 1249.63 | P3: Летко Иван Иванович | Q3: letko.ii@tc11.pp.gazprom-neft.ru | R3: =VLOOKUP(Таблица3[[#This Row],[Комментарий]],Справочник!$A$6:$B$4224,2,0) -> Начальник управления
A4: 3 | B4: Учетная запись | C4: abdeev.am | D4: ТЕКУЩИЙ ПЕРИОД | E4: Учетная запись ВКС | F4: 1249.63 | G4: 1 | H4: 28 | I4: 1249.63 | J4: 96.84 | K4: 100 | L4: 0 | M4: 1249.63 | P4: Абдеев Алик Мидхатович | Q4: abdeev.am@tc11.pp.gazprom-neft.ru | R4: =VLOOKUP(Таблица3[[#This Row],[Комментарий]],Справочник!$A$6:$B$4224,2,0) -> Руководитель направления по сопровождению гидроразрыва пластов
A5: 4 | B5: Учетная запись | C5: abdullin.tr | D5: ТЕКУЩИЙ ПЕРИОД | E5: Учетная запись ВКС | F5: 1249.63 | G5: 1 | H5: 28 | I5: 1249.63 | J5: 96.84 | K5: 100 | L5: 0 | M5: 1249.63 | P5: Абдуллин Тагир Рафаэлевич | Q5: abdullin.tr@tc15.pp.gazprom-neft.ru | R5: =VLOOKUP(Таблица3[[#This Row],[Комментарий]],Справочник!$A$6:$B$4224,2,0) -> Ведущий инженер | S5: =[6]!ExtractElement(Таблица3[[#This Row],[Комментарий]],1," ") -> #NAME? | T5: =Таблица3[[#This Row],[Комментарий]] -> Абдуллин Тагир Рафаэлевич
A6: 5 | B6: Учетная запись | C6: abzalova.gr | D6: ТЕКУЩИЙ ПЕРИОД | E6: Учетная запись ВКС | F6: 1249.63 | G6: 1 | H6: 28 | I6: 1249.63 | J6: 96.84 | K6: 100 | L6: 0 | M6: 1249.63 | P6: Абзалова Гульшат Радисовна | Q6: abzalova.gr@tc15.pp.gazprom-neft.ru | R6: =VLOOKUP(Таблица3[[#This Row],[Комментарий]],Справочник!$A$6:$B$4224,2,0) -> Заведующий лабораторией
A7: 6 | B7: Учетная запись | C7: abileva.nm | D7: ТЕКУЩИЙ ПЕРИОД | E7: Учетная запись ВКС | F7: 1249.63 | G7: 1 | H7: 28 | I7: 1249.63 | J7: 96.84 | K7: 100 | L7: 0 | M7: 1249.63 | P7: Абилева Наиля Малдыбаевна | Q7: abileva.nm@tc11.pp.gazprom-neft.ru | R7: =VLOOKUP(Таблица3[[#This Row],[Комментарий]],Справочник!$A$6:$B$4224,2,0) -> РН по капитальному строительству, капитальному ремонту
A8: 7 | B8: Учетная запись | C8: avkhadiev.da | D8: ТЕКУЩИЙ ПЕРИОД | E8: Учетная запись ВКС | F8: 1249.63 | G8: 1 | H8: 28 | I8: 1249.63 | J8: 96.84 | K8: 100 | L8: 0 | M8: 1249.63 | P8: Авхадиев Денис Анварович | Q8: avkhadiev.da@tc15.pp.gazprom-neft.ru | R8: =VLOOKUP(Таблица3[[#This Row],[Комментарий]],Справочник!$A$6:$B$4224,2,0) -> Главный специалист
A9: 8 | B9: Учетная запись | C9: agafonova.da | D9: ТЕКУЩИЙ ПЕРИОД | E9: Учетная запись ВКС | F9: 1249.63 | G9: 1 | H9: 28 | I9: 1249.63 | J9: 96.84 | K9: 100 | L9: 0 | M9: 1249.63 | P9: Агафонова Дарья Анатольевна | Q9: agafonova.da@tc6.pp.gazprom-neft.ru | R9: =VLOOKUP(Таблица3[[#This Row],[Комментарий]],Справочник!$A$6:$B$4224,2,0) -> Ведущий специалист
A10: 9 | B10: Учетная запись | C10: agliullin.im | D10: ТЕКУЩИЙ ПЕРИОД | E10: Учетная запись ВКС | F10: 1249.63 | G10: 1 | H10: 28 | I10: 1249.63 | J10: 96.84 | K10: 100 | L10: 0 | M10: 1249.63 | P10: Аглиуллин Ильгиз Мазитович | Q10: agliullin.im@tc17.pp.gazprom-neft.ru | R10: =VLOOKUP(Таблица3[[#This Row],[Комментарий]],Справочник!$A$6:$B$4224,2,0) -> Специалист
A11: 10 | B11: Учетная запись | C11: adamanyuk.if | D11: ТЕКУЩИЙ ПЕРИОД | E11: Учетная запись ВКС | F11: 1249.63 | G11: 1 | H11: 28 | I11: 1249.63 | J11: 96.84 | K11: 100 | L11: 0 | M11: 1249.63 | P11: Адаманюк Инна Федоровна | Q11: adamanyuk.if@tc11.pp.gazprom-neft.ru | R11: =VLOOKUP(Таблица3[[#This Row],[Комментарий]],Справочник!$A$6:$B$4224,2,0) -> Главный специалист
A12: 11 | B12: Учетная запись | C12: adilov.ssh | D12: ТЕКУЩИЙ ПЕРИОД | E12: Учетная запись ВКС | F12: 1249.63 | G12: 1 | H12: 28 | I12: 1249.63 | J12: 96.84 | K12: 100 | L12: 0 | M12: 1249.63 | P12: Адилов Саидбек Шахсолтанович | Q12: adilov.ssh@tc15.pp.gazprom-neft.ru | R12: =VLOOKUP(Таблица3[[#This Row],[Комментарий]],Справочник!$A$6:$B$4224,2,0) -> Механик
A13: 12 | B13: Учетная запись | C13: adigezalov.an | D13: ТЕКУЩИЙ ПЕРИОД | E13: Учетная запись ВКС | F13: 1249.63 | G13: 1 | H13: 28 | I13: 1249.63 | J13: 96.84 | K13: 100 | L13: 0 | M13: 1249.63 | P13: Адыгезалов Ализаде Нуру Оглы | Q13: adigezalov.an@tc11.pp.gazprom-neft.ru | R13: =VLOOKUP(Таблица3[[#This Row],[Комментарий]],Справочник!$A$6:$B$4224,2,0) -> Начальник цеха
A14: 13 | B14: Учетная запись | C14: azarova.av | D14: ТЕКУЩИЙ ПЕРИОД | E14: Учетная запись ВКС | F14: 1249.63 | G14: 1 | H14: 28 | I14: 1249.63 | J14: 96.84 | K14: 100 | L14: 0 | M14: 1249.63 | P14: Азарова Алена Валерьевна | Q14: azarova.av@tc11.pp.gazprom-neft.ru | R14: =VLOOKUP(Таблица3[[#This Row],[Комментарий]],Справочник!$A$6:$B$4224,2,0) -> Ведущий специалист | S14: =[6]!ExtractElement(Таблица3[[#This Row],[Комментарий]],1," ") -> #NAME? | T14: =Таблица3[[#This Row],[Комментарий]] -> Азарова Алена Валерьевна
A15: 14 | B15: Учетная запись | C15: azyazov.da | D15: ТЕКУЩИЙ ПЕРИОД | E15: Учетная запись ВКС | F15: 1249.63 | G15: 1 | H15: 28 | I15: 1249.63 | J15: 96.84 | K15: 100 | L15: 0 | M15: 1249.63 | P15: Азязов Денис Александрович | Q15: azyazov.da@tc11.pp.gazprom-neft.ru | R15: =VLOOKUP(Таблица3[[#This Row],[Комментарий]],Справочник!$A$6:$B$4224,2,0) -> Руководитель направления нефтесервисных услуг и услуг общего профиля
A16: 15 | B16: Учетная запись | C16: ajnulin.rr | D16: ТЕКУЩИЙ ПЕРИОД | E16: Учетная запись ВКС | F16: 1249.63 | G16: 1 | H16: 28 | I16: 1249.63 | J16: 96.84 | K16: 100 | L16: 0 | M16: 1249.63 | P16: Айнулин Рустам Рашидович | Q16: ajnulin.rr@tc11.pp.gazprom-neft.ru | R16: =VLOOKUP(Таблица3[[#This Row],[Комментарий]],Справочник!$A$6:$B$4224,2,0) -> Главный сварщик
A17: 16 | B17: Учетная запись | C17: aytmukhametov.rr | D17: ТЕКУЩИЙ ПЕРИОД | E17: Учетная запись ВКС | F17: 1249.63 | G17: 1 | H17: 28 | I17: 1249.63 | J17: 96.84 | K17: 100 | L17: 0 | M17: 1249.63 | P17: Айтмухаметов Рамиль Раисович | Q17: aytmukhametov.rr@tc17.pp.gazprom-neft.ru | R17: =VLOOKUP(Таблица3[[#This Row],[Комментарий]],Справочник!$A$6:$B$4224,2,0) -> Мастер бр. № 8
A18: 17 | B18: Учетная запись | C18: akberdiev.bo | D18: ТЕКУЩИЙ ПЕРИОД | E18: Учетная запись ВКС | F18: 1249.63 | G18: 1 | H18: 28 | I18: 1249.63 | J18: 96.84 | K18: 100 | L18: 0 | M18: 1249.63 | P18: Акбердиев Булат Омурбекович | Q18: akberdiev.bo@tc15.pp.gazprom-neft.ru | R18: =VLOOKUP(Таблица3[[#This Row],[Комментарий]],Справочник!$A$6:$B$4224,2,0) -> Заместитель начальника цеха добычи и подготовки нефти
A19: 18 | B19: Учетная запись | C19: akzigitov.rs | D19: ТЕКУЩИЙ ПЕРИОД | E19: Учетная запись ВКС | F19: 1249.63 | G19: 1 | H19: 28 | I19: 1249.63 | J19: 96.84 | K19: 100 | L19: 0 | M19: 1249.63 | P19: Акзигитов Рафаэль Сайфуллович | Q19: akzigitov.rs@tc16.pp.gazprom-neft.ru | R19: =VLOOKUP(Таблица3[[#This Row],[Комментарий]],Справочник!$A$6:$B$4224,2,0) -> Мастер по ДНГиК бр.№9 ДНС-2 Ватинского м/р
A20: 19 | B20: Учетная запись | C20: aleksandrov.sv | D20: ТЕКУЩИЙ ПЕРИОД | E20: Учетная запись ВКС | F20: 1249.63 | G20: 1 | H20: 28 | I20: 1249.63 | J20: 96.84 | K20: 100 | L20: 0 | M20: 1249.63 | P20: Александров Сергей Валерьевич | Q20: aleksandrov.sv@tc17.pp.gazprom-neft.ru | R20: =VLOOKUP(Таблица3[[#This Row],[Комментарий]],Справочник!$A$6:$B$4224,2,0) -> Руководитель направления по производственной безопасности
A21: 20 | B21: Учетная запись | C21: alekhina.gv | D21: ТЕКУЩИЙ ПЕРИОД | E21: Учетная запись ВКС | F21: 1249.63 | G21: 1 | H21: 28 | I21: 1249.63 | J21: 96.84 | K21: 100 | L21: 0 | M21: 1249.63 | P21: Алехина Галина Владимировна | Q21: alekhina.gv@tc11.pp.gazprom-neft.ru | R21: =VLOOKUP(Таблица3[[#This Row],[Комментарий]],Справочник!$A$6:$B$4224,2,0) -> Техник
A22: 21 | B22: Учетная запись | C22: aleshina.ava | D22: ТЕКУЩИЙ ПЕРИОД | E22: Учетная запись ВКС | F22: 1249.63 | G22: 1 | H22: 28 | I22: 1249.63 | J22: 96.84 | K22: 100 | L22: 0 | M22: 1249.63 | P22: Алешина Алина Валентиновна | Q22: aleshina.ava@tc17.pp.gazprom-neft.ru | R22: =VLOOKUP(Таблица3[[#This Row],[Комментарий]],Справочник!$A$6:$B$4224,2,0) -> Ведущий специалист
A23: 22 | B23: Учетная запись | C23: aleshchenko.ip | D23: ТЕКУЩИЙ ПЕРИОД | E23: Учетная запись ВКС | F23: 1249.63 | G23: 1 | H23: 28 | I23: 1249.63 | J23: 96.84 | K23: 100 | L23: 0 | M23: 1249.63 | P23: Алещенко Иван Павлович | Q23: aleshchenko.ip@tc15.pp.gazprom-neft.ru | R23: =VLOOKUP(Таблица3[[#This Row],[Комментарий]],Справочник!$A$6:$B$4224,2,0) -> Руководитель направления по управлению данными
A24: 23 | B24: Учетная запись | C24: alipkachev.km | D24: ТЕКУЩИЙ ПЕРИОД | E24: Учетная запись ВКС | F24: 1249.63 | G24: 1 | H24: 28 | I24: 1249.63 | J24: 96.84 | K24: 100 | L24: 0 | M24: 1249.63 | P24: Алипкачев Казбек Магомедкамилович | Q24: alipkachev.km@tc14.pp.gazprom-neft.ru | R24: =VLOOKUP(Таблица3[[#This Row],[Комментарий]],Справочник!$A$6:$B$4224,2,0) -> Главный специалист
A25: 24 | B25: Учетная запись | C25: khabibullina.am | D25: ТЕКУЩИЙ ПЕРИОД | E25: Учетная запись ВКС | F25: 1249.63 | G25: 1 | H25: 28 | I25: 1249.63 | J25: 96.84 | K25: 100 | L25: 0 | M25: 1249.63 | P25: Хабибуллина Альмира Махияновна | Q25: khabibullina.am@tc11.pp.gazprom-neft.ru | R25: =VLOOKUP(Таблица3[[#This Row],[Комментарий]],Справочник!$A$6:$B$4224,2,0) -> Ведущий специалист
A26: 25 | B26: Учетная запись | C26: afanaseva.tr | D26: ТЕКУЩИЙ ПЕРИОД | E26: Учетная запись ВКС | F26: 1249.63 | G26: 1 | H26: 28 | I26: 1249.63 | J26: 96.84 | K26: 100 | L26: 0 | M26: 1249.63 | P26: Афанасьева Татьяна Рузилевна | Q26: afanaseva.tr@tc11.pp.gazprom-neft.ru | R26: =VLOOKUP(Таблица3[[#This Row],[Комментарий]],Справочник!$A$6:$B$4224,2,0) -> Руководитель направления по интеграции
... A29: 28 | B29: Учетная запись | C29: aldabirov.im | D29: ТЕКУЩИЙ ПЕРИОД | E29: Учетная запись ВКС | F29: 1249.63 | G29: 1 | H29: 28 | I29: 1249.63 | J29: 96.84 | K29: 100 | L29: 0 | M29: 1249.63 | P29: Альдабиров Ибрагим Мусаевич | Q29: aldabirov.im@tc7.pp.gazprom-neft.ru | R29: =VLOOKUP(Таблица3[[#This Row],[Комментарий]],Справочник!$A$6:$B$4224,2,0) -> Руководитель направления
A30: 29 | B30: Учетная запись | C30: alkhovik.ra | D30: ТЕКУЩИЙ ПЕРИОД | E30: Учетная запись ВКС | F30: 1249.63 | G30: 1 | H30: 28 | I30: 1249.63 | J30: 96.84 | K30: 100 | L30: 0 | M30: 1249.63 | P30: Альховик Руслан Анатольевич | Q30: alkhovik.ra@tc14.pp.gazprom-neft.ru | R30: =VLOOKUP(Таблица3[[#This Row],[Комментарий]],Справочник!$A$6:$B$4224,2,0) -> Старший механик | S30: =[6]!ExtractElement(Таблица3[[#This Row],[Комментарий]],1," ") -> #NAME? | T30: =Таблица3[[#This Row],[Комментарий]] -> Альховик Руслан Анатольевич
A31: 30 | B31: Учетная запись | C31: alkhovik.yuv | D31: ТЕКУЩИЙ ПЕРИОД | E31: Учетная запись ВКС | F31: 1249.63 | G31: 1 | H31: 28 | I31: 1249.63 | J31: 96.84 | K31: 100 | L31: 0 | M31: 1249.63 | P31: Альховик Юлия Валентиновна | Q31: alkhovik.yuv@tc20.pp.gazprom-neft.ru | R31: =VLOOKUP(Таблица3[[#This Row],[Комментарий]],Справочник!$A$6:$B$4224,2,0) -> Инженер по ООС
A32: 31 | B32: Учетная запись | C32: amineva.oa | D32: ТЕКУЩИЙ ПЕРИОД | E32: Учетная запись ВКС | F32: 1249.63 | G32: 1 | H32: 28 | I32: 1249.63 | J32: 96.84 | K32: 100 | L32: 0 | M32: 1249.63 | P32: Аминева Ольга Александровна | Q32: amineva.oa@tc14.pp.gazprom-neft.ru | R32: =VLOOKUP(Таблица3[[#This Row],[Комментарий]],Справочник!$A$6:$B$4224,2,0) -> Ведущий инженер
A33: 32 | B33: Учетная запись | C33: amirov.az | D33: ТЕКУЩИЙ ПЕРИОД | E33: Учетная запись ВКС | F33: 1249.63 | G33: 1 | H33: 28 | I33: 1249.63 | J33: 96.84 | K33: 100 | L33: 0 | M33: 1249.63 | P33: Амиров Артур Зинурович | Q33: #N/A | R33: =VLOOKUP(Таблица3[[#This Row],[Комментарий]],Справочник!$A$6:$B$4224,2,0) -> #N/A | S33: =VLOOKUP(Таблица3[[#This Row],[Комментарий]],[7]Лист_1!$H$2:$J$15000,3,0) -> #N/A | T33: уволен
A34: 33 | B34: Учетная запись | C34: ananin.in | D34: ТЕКУЩИЙ ПЕРИОД | E34: Учетная запись ВКС | F34: 1249.63 | G34: 1 | H34: 28 | I34: 1249.63 | J34: 96.84 | K34: 100 | L34: 0 | M34: 1249.63 | P34: Ананин Игорь Николаевич | Q34: ananin.in@tc15.pp.gazprom-neft.ru | R34: =VLOOKUP(Таблица3[[#This Row],[Комментарий]],Справочник!$A$6:$B$4224,2,0) -> Главный специалист
A35: 34 | B35: Учетная запись | C35: andieva.tf | D35: ТЕКУЩИЙ ПЕРИОД | E35: Учетная запись ВКС | F35: 1249.63 | G35: 1 | H35: 28 | I35: 1249.63 | J35: 96.84 | K35: 100 | L35: 0 | M35: 1249.63 | P35: Андиева Татьяна Федоровна | Q35: andieva.tf@tc8.pp.gazprom-neft.ru | R35: =VLOOKUP(Таблица3[[#This Row],[Комментарий]],Справочник!$A$6:$B$4224,2,0) -> Главный специалист
A36: 35 | B36: Учетная запись | C36: andreev.ayur | D36: ТЕКУЩИЙ ПЕРИОД | E36: Учетная запись ВКС | F36: 1249.63 | G36: 1 | H36: 28 | I36: 1249.63 | J36: 96.84 | K36: 100 | L36: 0 | M36: 1249.63 | P36: Андреев Александр Юрьевич | Q36: andreev.ayur@tc11.pp.gazprom-neft.ru | R36: =VLOOKUP(Таблица3[[#This Row],[Комментарий]],Справочник!$A$6:$B$4224,2,0) -> Руководитель проекта
A37: 36 | B37: Учетная запись | C37: andreev.aalek | D37: ТЕКУЩИЙ ПЕРИОД | E37: Учетная запись ВКС | F37: 1249.63 | G37: 1 | H37: 28 | I37: 1249.63 | J37: 96.84 | K37: 100 | L37: 0 | M37: 1249.63 | P37: Андреев Андрей Алексеевич | Q37: andreev.aalek@tc11.pp.gazprom-neft.ru | R37: =VLOOKUP(Таблица3[[#This Row],[Комментарий]],Справочник!$A$6:$B$4224,2,0) -> Главный специалист
A38: 37 | B38: Учетная запись | C38: andriyanova.ev | D38: ТЕКУЩИЙ ПЕРИОД | E38: Учетная запись ВКС | F38: 1249.63 | G38: 1 | H38: 28 | I38: 1249.63 | J38: 96.84 | K38: 100 | L38: 0 | M38: 1249.63 | P38: Андриянова Елена Викторовна | Q38: andriyanova.ev@tc18.pp.gazprom-neft.ru | R38: =VLOOKUP(Таблица3[[#This Row],[Комментарий]],Справочник!$A$6:$B$4224,2,0) -> Ведущий специалист | S38: =[6]!ExtractElement(Таблица3[[#This Row],[Комментарий]],1," ") -> #NAME? | T38: =Таблица3[[#This Row],[Комментарий]] -> Андриянова Елена Викторовна
A39: 38 | B39: Учетная запись | C39: andronov.av | D39: ТЕКУЩИЙ ПЕРИОД | E39: Учетная запись ВКС | F39: 1249.63 | G39: 1 | H39: 28 | I39: 1249.63 | J39: 96.84 | K39: 100 | L39: 0 | M39: 1249.63 | P39: Андронов Андрей Валентинович | Q39: andronov.av@tc6.pp.gazprom-neft.ru | R39: =VLOOKUP(Таблица3[[#This Row],[Комментарий]],Справочник!$A$6:$B$4224,2,0) -> Руководитель направления
A40: 39 | B40: Учетная запись | C40: androschuk.vv | D40: ТЕКУЩИЙ ПЕРИОД | E40: Учетная запись ВКС | F40: 1249.63 | G40: 1 | H40: 28 | I40: 1249.63 | J40: 96.84 | K40: 100 | L40: 0 | M40: 1249.63 | P40: Андрощук Василий Васильевич | Q40: androschuk.vv@tc21.pp.gazprom-neft.ru | R40: =VLOOKUP(Таблица3[[#This Row],[Комментарий]],Справочник!$A$6:$B$4224,2,0) -> Старший механик
A41: 40 | B41: Учетная запись | C41: andryushov.an | D41: ТЕКУЩИЙ ПЕРИОД | E41: Учетная запись ВКС | F41: 1249.63 | G41: 1 | H41: 28 | I41: 1249.63 | J41: 96.84 | K41: 100 | L41: 0 | M41: 1249.63 | P41: Андрюшов Андрей Николаевич | Q41: andryushov.an@tc12.pp.gazprom-neft.ru | R41: =VLOOKUP(Таблица3[[#This Row],[Комментарий]],Справочник!$A$6:$B$4224,2,0) -> Руководитель группы
A42: 41 | B42: Учетная запись | C42: anoshina.on | D42: ТЕКУЩИЙ ПЕРИОД | E42: Учетная запись ВКС | F42: 1249.63 | G42: 1 | H42: 28 | I42: 1249.63 | J42: 96.84 | K42: 100 | L42: 0 | M42: 1249.63 | P42: Аношина Ольга Николаевна | Q42: anoshina.on@tc7.pp.gazprom-neft.ru | R42: =VLOOKUP(Таблица3[[#This Row],[Комментарий]],Справочник!$A$6:$B$4224,2,0) -> Начальник отдела | S42: =[6]!ExtractElement(Таблица3[[#This Row],[Комментарий]],1," ") -> #NAME? | T42: =Таблица3[[#This Row],[Комментарий]] -> Аношина Ольга Николаевна
...
